<?xml version="1.0"?>
<robot xmlns:xacro="http://www.ros.org/wiki/xacro">

  <!-- Constants -->
  <xacro:property name="pi_const" value="3.141592653589793"/>

  <!-- Materials -->
  <material name="white">
    <color rgba="1 1 1 1"/>
  </material>
  <material name="orange">
    <color rgba="1 0.3 0.1 1"/>
  </material>
  <material name="blue">
    <color rgba="0.2 0.2 1 1"/>
  </material>
  <material name="black">
    <color rgba="0 0 0 1"/>
  </material>

  <!-- BASE LINK -->
  <link name="base_link">
    <inertial>
      <origin xyz="0 0 0" rpy="0 0 0"/>
      <mass value="0.1"/>
      <inertia ixx="0.001" ixy="0" ixz="0" iyy="0.001" iyz="0" izz="0.001"/>
    </inertial>
  </link>

  <!-- CHASSIS -->
  <joint name="chassis_joint" type="fixed">
    <parent link="base_link"/>
    <child link="chassis"/>
    <origin xyz="-0.1 0 0"/>
  </joint>

  <link name="chassis">
    <visual>
      <origin xyz="0.15 0 0.075" rpy="0 0 0"/>
      <geometry>
        <box size="0.3 0.3 0.15"/>
      </geometry>
      <material name="white"/>
    </visual>
    <collision>
      <origin xyz="0.15 0 0.075" rpy="0 0 0"/>
      <geometry>
        <box size="0.3 0.3 0.15"/>
      </geometry>
    </collision>
    <xacro:inertial_box mass="0.5" x="0.3" y="0.3" z="0.15">
      <origin xyz="0.15 0 0.075" rpy="0 0 0"/>
    </xacro:inertial_box>
  </link>

  <!-- LEFT WHEEL -->
  <joint name="left_wheel_joint" type="continuous">
    <parent link="base_link"/>
    <child link="left_wheel"/>
    <origin xyz="0 0.175 0" rpy="-${pi_const/2} 0 0"/>
    <axis xyz="0 0 1"/>
  </joint>

  <link name="left_wheel">
    <visual>
      <origin xyz="0 0 0" rpy="0 0 0"/>
      <geometry>
        <cylinder length="0.04" radius="0.05"/>
      </geometry>
      <material name="blue"/>
    </visual>
    <collision>
      <origin xyz="0 0 0" rpy="0 0 0"/>
      <geometry>
        <cylinder length="0.04" radius="0.05"/>
      </geometry>
    </collision>
    <xacro:inertial_cylinder mass="0.1" length="0.04" radius="0.05">
      <origin xyz="0 0 0" rpy="0 0 0"/>
    </xacro:inertial_cylinder>
  </link>

  <!-- RIGHT WHEEL -->
  <joint name="right_wheel_joint" type="continuous">
    <parent link="base_link"/>
    <child link="right_wheel"/>
    <origin xyz="0 -0.175 0" rpy="${pi_const/2} 0 0"/>
    <axis xyz="0 0 -1"/>
  </joint>

  <link name="right_wheel">
    <visual>
      <origin xyz="0 0 0" rpy="0 0 0"/>
      <geometry>
        <cylinder length="0.04" radius="0.05"/>
      </geometry>
      <material name="blue"/>
    </visual>
    <collision>
      <origin xyz="0 0 0" rpy="0 0 0"/>
      <geometry>
        <cylinder length="0.04" radius="0.05"/>
      </geometry>
    </collision>
    <xacro:inertial_cylinder mass="0.1" length="0.04" radius="0.05">
      <origin xyz="0 0 0" rpy="0 0 0"/>
    </xacro:inertial_cylinder>
  </link>

  <!-- CASTER WHEEL -->
  <joint name="caster_wheel_joint" type="fixed">
    <parent link="chassis"/>
    <child link="caster_wheel"/>
    <origin xyz="0.24 0 0" rpy="0 0 0"/>
  </joint>

  <link name="caster_wheel">
    <visual>
      <origin xyz="0 0 0" rpy="0 0 0"/>
      <geometry>
        <sphere radius="0.05"/>
      </geometry>
      <material name="black"/>
    </visual>
    <collision>
      <origin xyz="0 0 0" rpy="0 0 0"/>
      <geometry>
        <sphere radius="0.05"/>
      </geometry>
    </collision>
    <xacro:inertial_sphere mass="0.1" radius="0.05">
      <origin xyz="0 0 0" rpy="0 0 0"/>
    </xacro:inertial_sphere>
  </link>

  <!-- Gazebo plugins for differential drive -->
  <gazebo reference="base_link">
  </gazebo>

  <gazebo reference="chassis">
    <material>Gazebo/White</material>
    <friction>
      <ode>
        <mu>0.6</mu>
        <mu2>0.6</mu2>
      </ode>
    </friction>
  </gazebo>

  <gazebo reference="left_wheel">
    <material>Gazebo/Blue</material>
    <friction>
      <ode>
        <mu>0.8</mu>
        <mu2>0.8</mu2>
        <slip1>0.01</slip1>
        <slip2>0.01</slip2>
      </ode>
    </friction>
  </gazebo>

  <gazebo reference="right_wheel">
    <material>Gazebo/Blue</material>
    <friction>
      <ode>
        <mu>0.8</mu>
        <mu2>0.8</mu2>
        <slip1>0.01</slip1>
        <slip2>0.01</slip2>
      </ode>
    </friction>
  </gazebo>

  <gazebo reference="caster_wheel">
    <material>Gazebo/Black</material>
    <friction>
      <ode>
        <mu>0.01</mu>
        <mu2>0.01</mu2>
      </ode>
    </friction>
  </gazebo>


</robot>
